Workbook
Name Age_Groups: Customer_Helper!$P$1:$S$6
Name City_Assignment: Salesperson_Helper!$H$1:$I$11
Name City_Master: Customer_Helper!$F$1:$H$13
Name Customer_Segments: Orders_Helper!$J$1:$L$4
Name Customer_Types: Customer_Helper!$J$1:$K$4
Name Electronics_Products: #REF!
Name First_Names: Customer_Helper!$A$1:$B$101
Name Furniture_Products: #REF!
Name Gender_Distribution: Customer_Helper!$M$1:$N$3
Name Last_Names: Customer_Helper!$D$1:$D$51
Name Monthly_Distribution: Orders_Helper!$F$1:$H$12
Name Order_Distribution: Orders_Helper!$A$1:$D$4
Name Product_MasterData: Product_Masterdata!$A$1:$L$22
Name Raw_Data: Raw_data!#REF!
Name Region: Salesperson_Helper!$K$1:$L$13
Name Salesperson_Master: Salesperson_Masterdata!$A$1:$F$11
Name Salesperson_Names: Salesperson_Helper!$A$1:$C$11
Name Seasonal_Mapping: Master_data!$A$15:$B$27
Name tbl_cities: Master_data!$A$1:$B$13
Name tbl_paymentmode: Master_data!$N$1:$N$6
Name tbl_products: Master_data!$E$1:$G$31
Name tbl_saleschannel: Master_data!$P$1:$P$3
Name tbl_salesperson: Master_data!$J$1:$K$11
Name Team_Assignment: Salesperson_Helper!$E$1:$F$11
Name Weekly_Behaviour: Orders_Helper!$N$1:$O$8

Sheet Dashboard
A1: NOVAMART RETAIL SALES AND PROFIT ANALYSIS | AA1: Rank | AB1: Product | AC1: Revenue | AD1: Revenue Lable
AA2: =ROW(Y1) -> 1 | AB2: =INDEX(Product_Analysis[Product],MATCH(AC2,Product_Analysis[Revenue],0)) -> Laptop | AC2: =LARGE(Product_Analysis[Revenue],AA2) -> 24771000 | AD2: ="₹"&TEXT(Product_helper_Dashboard[[#This Row],[Revenue]]/10000000,"0.00")&" Cr" -> ₹2.48 Cr | AF2: =SUM(RawData[Revenue]) -> 1.2407907e+08
A3: FY 2025 | Sales Performance Dashboard | AA3: =ROW(Y2) -> 2 | AB3: =INDEX(Product_Analysis[Product],MATCH(AC3,Product_Analysis[Revenue],0)) -> Sofa | AC3: =LARGE(Product_Analysis[Revenue],AA3) -> 16882267 | AD3: ="₹"&TEXT(Product_helper_Dashboard[[#This Row],[Revenue]]/10000000,"0.00")&" Cr" -> ₹1.69 Cr | AF3: =SUM(RawData[Profit]) -> 17118773
AA4: =ROW(Y3) -> 3 | AB4: =INDEX(Product_Analysis[Product],MATCH(AC4,Product_Analysis[Revenue],0)) -> Smartphone | AC4: =LARGE(Product_Analysis[Revenue],AA4) -> 16236016 | AD4: ="₹"&TEXT(Product_helper_Dashboard[[#This Row],[Revenue]]/10000000,"0.00")&" Cr" -> ₹1.62 Cr | AF4: =ROWS(RawData[Order_ID]) -> 3000
A5: Total Revenue | C5: Total Profit | E5: Profit Margin | G5: Total Orders | I5: Units Sold | K5: Customers | M5: Avg. Order Value | AA5: =ROW(Y4) -> 4 | AB5: =INDEX(Product_Analysis[Product],MATCH(AC5,Product_Analysis[Revenue],0)) -> Wardrobe | AC5: =LARGE(Product_Analysis[Revenue],AA5) -> 12427452 | AD5: ="₹"&TEXT(Product_helper_Dashboard[[#This Row],[Revenue]]/10000000,"0.00")&" Cr" -> ₹1.24 Cr
A6: ="₹"&TEXT(AF2/10000000,"0.00")&" Cr" -> ₹12.41 Cr | C6: ="₹"&TEXT(AF3/10000000,"0.00")&" Cr" -> ₹1.71 Cr | E6: =SUM(RawData[Profit])/SUM(RawData[Revenue]) -> 0.13796665 | G6: =ROWS(RawData[Order_ID]) -> 3000 | I6: =SUM(RawData[Quantity]) -> 9029 | K6: =COUNTA(Customer_Masterdata[Customer_ID]) -> 900 | M6: ="₹"&TEXT(AF6/1000,"0.00")&" K" -> ₹41.36 K | AA6: =ROW(Y5) -> 5 | AB6: =INDEX(Product_Analysis[Product],MATCH(AC6,Product_Analysis[Revenue],0)) -> Tablet | AC6: =LARGE(Product_Analysis[Revenue],AA6) -> 11092822 | AD6: ="₹"&TEXT(Product_helper_Dashboard[[#This Row],[Revenue]]/10000000,"0.00")&" Cr" -> ₹1.11 Cr | AF6: =AF2/AF4 -> 41359.689
A71: Key Business Insights
A72: Insight 1 | C72: Insight 2 | F72: Insight 3 | I72: Insight 4 | L72: Insight 5
A73: West is NovaMart's strongest region | C73: Electronics drives revenue, while Office Supplies drives margin | F73: Occasional and Loyal customers drive the business | I73: November–December show a major profitability decline | L73: High-revenue products require margin protection
A77: ⚠️ Profitability Alert: November and December margins declined sharply to 6.99% and 6.10%, compared with ~14.7–15.4% in most other months. The decline is concentrated in Electronics and Furniture and coincides with high seasonal discounts
A80: Margin Insight: Electronics and Furniture experienced substantial margin compression during the festival period, while Office Supplies remained consistently above 27% margin.

Sheet Analysis
A1: Metric | B1: My Excel Result | D1: Category Analysis | L1: Monthly Analysis | T1: Category and Seasonal Analysis | AD1: Product Analysis | AL1: Customer Analysis | AU1: Customer Segment Summary | BG1: Top 10 Customers by revenue | BN1: Top 10 Customers by Profit | BU1: Sales Channel Analysis | CC1: Payment Mode Analysis | CK1: Salesperson Analysis | CU1: City Performance | DC1: Region Performance | DK1: Profit_Drop_Analysis | DQ1: Product_Level_Investigation | DY1: Monthly Analysis | EG1: Product_Discount_Analysis
A2: Total Transactions | B2: =COUNTA(RawData[Order_ID]) -> 3000 | D2: Category | E2: Orders | F2: Units Sold | G2: Revenue | H2: Cost | I2: Profit | J2: Profit Margin | L2: Month | M2: Month Number | N2: Orders | O2: Units Sold | P2: Revenue | Q2: Profit | R2: Profit Margin | T2: Category | U2: Season | V2: Orders | W2: Units Sold | X2: Revenue | Y2: Profit | Z2: Profit Margin | AA2: Revenue Lable | AB2: Profit Lable | AD2: Product | AE2: Category | AF2: Orders | AG2: Units Sold | AH2: Revenue | AI2: Profit | AJ2: Profit Margin | AL2: Customer ID | AM2: Customer Name | AN2: Orders | AO2: Units Sold | AP2: Revenue | AQ2: Profit | AR2: AOV | AS2: Customer Type | AU2: Customer Type | AV2: Customers | AW2: Orders | AX2: Units | AY2: Revenue | AZ2: Profit | BA2: Profit Margin | BB2: Avg Revenue per Customer | BC2: Avg Profit per Customer | BD2: Avg Orders per Customer | BE2: Revenue Lable | BG2: Rank | BH2: Customer ID | BI2: Customer Name | BJ2: Orders | BK2: Revenue | BL2: Profit | BN2: Rank | BO2: Customer ID | BP2: Customer Name | BQ2: Orders | BR2: Revenue | BS2: Profit | BU2: Sales Channel | BV2: Orders | BW2: Units Sold | BX2: Revenue | BY2: Profit | BZ2: Profit Margin | CA2: Revenue Lable | CC2: Payment Mode | CD2: Orders | CE2: Units Sold | CF2: Revenue | CG2: Profit | CH2: Profit Margin | CI2: Revenue Lable | CK2: Salesperson ID | CL2: Salesperson Name | CM2: Orders | CN2: Units Sold | CO2: Revenue | CP2: Profit | CQ2: Profit Margin | CR2: Avg Order Value | CS2: Revenue Lable | CU2: City | CV2: Region | CW2: Orders | CX2: Units Sold | CY2: Revenue | CZ2: Profit | DA2: Profit Margin | DC2: Region | DD2: Orders | DE2: Units Sold | DF2: Revenue | DG2: Profit | DH2: Profit Margin | DI2: Revenue Lable | DK2: Month | DL2: Category | DM2: Revenue | DN2: Profit | DO2: Margin | DQ2: Product | DR2: Nov Revenue | DS2: Nov Profit | DT2: Nov Margin | DU2: Dec Revenue | DV2: Dec Profit | DW2: Dec Margin | DY2: Month | DZ2: Month Number | EA2: Orders | EB2: Units Sold | EC2: Revenue | ED2: Profit | EE2: Profit Margin | EG2: Product | EH2: Normal Margin | EI2: Nov Margin | EJ2: Nov Discount | EK2: Dec Margin | EL2: Dec Discount
A3: Unique products | B3: =SUMPRODUCT((RawData[Product_ID]<>"")/COUNTIF(RawData[Product_ID],RawData[Product_ID]&"")) -> 21 | D3: Electronics | E3: =COUNTIF(RawData[Product_Category],"Electronics") -> 1472 | F3: =SUMIF(RawData[Product_Category],"Electronics",RawData[Quantity]) -> 4460 | G3: =SUMIF(RawData[Product_Category],"Electronics",RawData[Revenue]) -> 73862420 | H3: =SUMIF(RawData[Product_Category],"Electronics",RawData[Total_Cost]) -> 64679145 | I3: =SUMIF(RawData[Product_Category],"Electronics",RawData[Profit]) -> 9183274.6 | J3: =I3/G3 -> 0.12432946 | L3: January | M3: =MONTH(L3&1) -> 1 | N3: =SUMPRODUCT(--(MONTH(RawData[Order_Date])= M3)) -> 292 | O3: =SUMPRODUCT((MONTH(RawData[Order_Date])=M3)*RawData[Quantity]) -> 860 | P3: =SUMPRODUCT((MONTH(RawData[Order_Date])=M3)*RawData[Revenue]) -> 11736181 | Q3: =SUMPRODUCT((MONTH(RawData[Order_Date])=M3)*RawData[Profit]) -> 1796861.2 | R3: =IFERROR(Q3/P3,0) -> 0.15310442 | T3: Electronics | U3: Regular | V3: =COUNTIFS(RawData[Product_Category],"Electronics",RawData[Order_Date],"<"&DATE(2025,11,1)) -> 1229 | W3: =SUMIFS(RawData[Quantity],RawData[Product_Category],"Electronics",RawData[Order_Date],"<"&DATE(2025,11,1)) -> 3710 | X3: =SUMIFS(RawData[Revenue],RawData[Product_Category],"Electronics",RawData[Order_Date],"<"&DATE(2025,11,1)) -> 62713704 | Y3: =SUMIFS(RawData[Profit],RawData[Product_Category],"Electronics",RawData[Order_Date],"<"&DATE(2025,11,1)) -> 8574838.7 | Z3: =Y3/X3 -> 0.13672991 | AA3: ="₹"&TEXT(Category_and_Seasonal_Analysis[[#This Row],[Revenue]]/10000000,"0.00")&" Cr" -> ₹6.27 Cr | AB3: ="₹"&TEXT(Category_and_Seasonal_Analysis[[#This Row],[Profit]]/100000,"0.00")&" L" -> ₹85.75 L | AD3: Laptop | AE3: Electronics | AF3: =COUNTIF(RawData[Product_Name],AD3) -> 150 | AG3: =SUMIF(RawData[Product_Name],AD3,RawData[Quantity]) -> 483 | AH3: =SUMIF(RawData[Product_Name],AD3,RawData[Revenue]) -> 24771000 | AI3: =SUMIF(RawData[Product_Name],AD3,RawData[Profit]) -> 2988095.7 | AJ3: =AI3/AH3 -> 0.12062879 | AL3: C0001 | AM3: Prachi Choudhary | AN3: =COUNTIF(RawData[Customer_ID],AL3) -> 2 | AO3: =SUMIF(RawData[Customer_ID],AL3,RawData[Quantity]) -> 9 | AP3: =SUMIF(RawData[Customer_ID],AL3,RawData[Revenue]) -> 37162.5 | AQ3: =SUMIF(RawData[Customer_ID],AL3,RawData[Profit]) -> 9787.5 | AR3: =IF(AN3=0,0,AP3/AN3) -> 18581.25 | AS3: =IF(AN3=1,"One-time",IF(AN3<=4,"Occasional",IF(AN3<=8,"Loyal","Review"))) -> Occasional | AU3: One-time | AV3: =COUNTIF(Customer_Analysis[Customer Type],AU3) -> 101 | AW3: =SUMIF(Customer_Analysis[Customer Type],AU3,Customer_Analysis[Orders]) -> 101 | AX3: =SUMIF(Customer_Analysis[Customer Type],AU3,Customer_Analysis[Units Sold]) -> 321 | AY3: =SUMIF(Customer_Analysis[Customer Type],AU3,Customer_Analysis[Revenue]) -> 3849440.8 | AZ3: =SUMIF(Customer_Analysis[Customer Type],AU3,Customer_Analysis[Profit]) -> 509725.48 | BA3: =AZ3/AY3 -> 0.13241546 | BB3: =AY3/AV3 -> 38113.275 | BC3: =AZ3/AV3 -> 5046.7869 | BD3: =AW3/AV3 -> 1 | BE3: ="₹"&TEXT(Customer_Segment_Analysis[[#This Row],[Revenue]]/10000000,"0.00")&" Cr" -> ₹0.38 Cr | BG3: 1 | BH3: C0012 | BI3: Trisha Jain | BJ3: 4 | BK3: 688035.24 | BL3: 83323.21 | BN3: 1 | BO3: C0846 | BP3: Nikita Saxena | BQ3: 7 | BR3: 586628.8 | BS3: 89714.14 | BU3: Online | BV3: =COUNTIF(RawData[Sales_Channel],BU3) -> 1139 | BW3: =SUMIF(RawData[Sales_Channel],BU3,RawData[Quantity]) -> 3351 | BX3: =SUMIF(RawData[Sales_Channel],BU3,RawData[Revenue]) -> 46169839 | BY3: =SUMIF(RawData[Sales_Channel],BU3,RawData[Profit]) -> 6425730.1 | BZ3: =BY3/BX3 -> 0.13917593 | CA3: ="₹"&TEXT(Sales_Channel_Analysis[[#This Row],[Revenue]]/10000000,"0.00")&" Cr" -> ₹4.62 Cr | CC3: UPI | CD3: =COUNTIF(RawData[Payment_Mode],CC3) -> 1160 | CE3: =SUMIF(RawData[Payment_Mode],CC3,RawData[Quantity]) -> 3548 | CF3: =SUMIF(RawData[Payment_Mode],CC3,RawData[Revenue]) -> 48443973 | CG3: =SUMIF(RawData[Payment_Mode],CC3,RawData[Profit]) -> 6615684.4 | CH3: =CG3/CF3 -> 0.13656362 | CI3: ="₹"&TEXT(Payment_Mode_Analysis[[#This Row],[Revenue]]/10000000,"0.00")&" Cr" -> ₹4.84 Cr | CK3: S001 | CL3: Aarav Patel | CM3: =COUNTIF(RawData[Salesperson_ID],CK3) -> 308 | CN3: =SUMIF(RawData[Salesperson_ID],CK3,RawData[Quantity]) -> 861 | CO3: =SUMIF(RawData[Salesperson_ID],CK3,RawData[Revenue]) -> 11723932 | CP3: =SUMIF(RawData[Salesperson_ID],CK3,RawData[Profit]) -> 1603525.7 | CQ3: =CP3/CO3 -> 0.13677372 | CR3: =IF(CM3=0,0,CO3/CM3) -> 38064.713 | CS3: ="₹"&TEXT(Table29[[#This Row],[Revenue]]/10000000,"0.00")&" Cr" -> ₹1.17 Cr | CU3: Mumbai | CV3: West | CW3: =COUNTIF(RawData[City],CU3) -> 238 | CX3: =SUMIF(RawData[City],CU3,RawData[Quantity]) -> 694 | CY3: =SUMIF(RawData[City],CU3,RawData[Revenue]) -> 9835614 | CZ3: =SUMIF(RawData[City],CU3,RawData[Profit]) -> 1335614 | DA3: =CZ3/CY3 -> 0.13579366 | DC3: North | DD3: =SUMIF(City_Analysis[Region],DC3,City_Analysis[Orders]) -> 749 | DE3: =SUMIF(City_Analysis[Region],DC3,City_Analysis[Units Sold]) -> 2271 | DF3: =SUMIF(City_Analysis[Region],DC3,City_Analysis[Revenue]) -> 31221257 | DG3: =SUMIF(City_Analysis[Region],DC3,City_Analysis[Profit]) -> 4345091 | DH3: =IF(DF3=0,0,DG3/DF3) -> 0.13917092 | DI3: ="₹"&TEXT(Region_Analysis[[#This Row],[Revenue]]/10000000,"0.00")&" Cr" -> ₹3.12 Cr | DK3: November | DL3: Electronics | DM3: =SUMIFS(RawData[Revenue],RawData[Product_Category],DL3, RawData[Order_Date],">="&DATE(2025,11,1),RawData[Order_Date],"<"&DATE(2025,12,1)) -> 5182808.7 | DN3: =SUMIFS(RawData[Profit],RawData[Product_Category],Profit_Drop_Analysis[[#This Row],[Category]], RawData[Order_Date],">="&DATE(2025,11,1),RawData[Order_Date],"<"&DATE(2025,12,1)) -> 327958.16 | DO3: =DN3/DM3 -> 0.063278076 | DQ3: Laptop | DR3: =SUMIFS(RawData[Revenue],RawData[Product_Name],DQ3, RawData[Order_Date],">="&DATE(2025,11,1),RawData[Order_Date],"<"&DATE(2025,12,1)) -> 946532.79 | DS3: =SUMIFS(RawData[Profit],RawData[Product_Name],DQ3, RawData[Order_Date],">="&DATE(2025,11,1),RawData[Order_Date],"<"&DATE(2025,12,1)) -> 44549.19 | DT3: =DS3/DR3 -> 0.04706566 | DU3: =SUMIFS(RawData[Revenue],RawData[Product_Name],DQ3, RawData[Order_Date],">="&DATE(2025,12,1),RawData[Order_Date],"<"&DATE(2026,1,1)) -> 1256177.2 | DV3: =SUMIFS(RawData[Profit],RawData[Product_Name],DQ3, RawData[Order_Date],">="&DATE(2025,12,1),RawData[Order_Date],"<"&DATE(2026,1,1)) -> 38499.3 | DW3: =DV3/DU3 -> 0.030647986 | DY3: January | DZ3: =MONTH(DY3&1) -> 1 | EA3: =SUMPRODUCT(--(MONTH(RawData[Order_Date])= DZ3)) -> 292 | EB3: =SUMPRODUCT((MONTH(RawData[Order_Date])=DZ3)*RawData[Quantity]) -> 860 | EC3: =SUMPRODUCT((MONTH(RawData[Order_Date])=DZ3)*RawData[Revenue]) -> 11736181 | ED3: =SUMPRODUCT((MONTH(RawData[Order_Date])=DZ3)*RawData[Profit]) -> 1796861.2 | EE3: =IFERROR(ED3/EC3,0) -> 0.15310442 | EG3: Laptop | EH3: =VLOOKUP(EG3,Product_Analysis[[Product]:[Profit Margin]],7,FALSE) -> 0.12062879 | EI3: 0.0471 | EJ3: =AVERAGEIFS(RawData[Discount%],RawData[Product_Name],EG3,RawData[Order_Date],">="&DATE(2025,11,1),RawData[Order_Date],"<"&DATE(2025,12,1)) -> 14.333333 | EK3: 0.030647986 | EL3: =AVERAGEIFS(RawData[Discount%],RawData[Product_Name],EG3,RawData[Order_Date],">="&DATE(2025,12,1),RawData[Order_Date],"<"&DATE(2026,1,1)) -> 15
A4: Unique Customers | B4: =SUMPRODUCT((RawData[Customer_ID]<>"")/COUNTIF(RawData[Customer_ID],RawData[Customer_ID]&"")) -> 864 | D4: Furniture | E4: =COUNTIF(RawData[Product_Category],"Furniture") -> 816 | F4: =SUMIF(RawData[Product_Category],"Furniture",RawData[Quantity]) -> 2423 | G4: =SUMIF(RawData[Product_Category],"Furniture",RawData[Revenue]) -> 49718569 | H4: =SUMIF(RawData[Product_Category],"Furniture",RawData[Total_Cost]) -> 41920658 | I4: =SUMIF(RawData[Product_Category],"Furniture",RawData[Profit]) -> 7797911 | J4: =I4/G4 -> 0.15684102 | L4: February | M4: =MONTH(L4&1) -> 2 | N4: =SUMPRODUCT(--(MONTH(RawData[Order_Date])= M4)) -> 222 | O4: =SUMPRODUCT((MONTH(RawData[Order_Date])=M4)*RawData[Quantity]) -> 658 | P4: =SUMPRODUCT((MONTH(RawData[Order_Date])=M4)*RawData[Revenue]) -> 9441583.4 | Q4: =SUMPRODUCT((MONTH(RawData[Order_Date])=M4)*RawData[Profit]) -> 1413047.1 | R4: =IFERROR(Q4/P4,0) -> 0.14966209 | T4: Electronics | U4: Festival | V4: =COUNTIFS(RawData[Product_Category],"Electronics",RawData[Order_Date],">="&DATE(2025,11,1)) -> 243 | W4: =SUMIFS(RawData[Quantity],RawData[Product_Category],"Electronics",RawData[Order_Date],">="&DATE(2025,11,1)) -> 750 | X4: =SUMIFS(RawData[Revenue],RawData[Product_Category],"Electronics",RawData[Order_Date],">="&DATE(2025,11,1)) -> 11148716 | Y4: =SUMIFS(RawData[Profit],RawData[Product_Category],"Electronics",RawData[Order_Date],">="&DATE(2025,11,1)) -> 608435.89 | Z4: =Y4/X4 -> 0.054574525 | AA4: ="₹"&TEXT(Category_and_Seasonal_Analysis[[#This Row],[Revenue]]/10000000,"0.00")&" Cr" -> ₹1.11 Cr | AB4: ="₹"&TEXT(Category_and_Seasonal_Analysis[[#This Row],[Profit]]/100000,"0.00")&" L" -> ₹6.08 L | AD4: Smartphone | AE4: Electronics | AF4: =COUNTIF(RawData[Product_Name],AD4) -> 165 | AG4: =SUMIF(RawData[Product_Name],AD4,RawData[Quantity]) -> 492 | AH4: =SUMIF(RawData[Product_Name],AD4,RawData[Revenue]) -> 16236016 | AI4: =SUMIF(RawData[Product_Name],AD4,RawData[Profit]) -> 2145136 | AJ4: =AI4/AH4 -> 0.13212207 | AL4: C0002 | AM4: Palak Pawar | AN4: =COUNTIF(RawData[Customer_ID],AL4) -> 2 | AO4: =SUMIF(RawData[Customer_ID],AL4,RawData[Quantity]) -> 5 | AP4: =SUMIF(RawData[Customer_ID],AL4,RawData[Revenue]) -> 4929 | AQ4: =SUMIF(RawData[Customer_ID],AL4,RawData[Profit]) -> 1545 | AR4: =IF(AN4=0,0,AP4/AN4) -> 2464.5 | AS4: =IF(AN4=1,"One-time",IF(AN4<=4,"Occasional",IF(AN4<=8,"Loyal","Review"))) -> Occasional | AU4: Occasional | AV4: =COUNTIF(Customer_Analysis[Customer Type],AU4) -> 568 | AW4: =SUMIF(Customer_Analysis[Customer Type],AU4,Customer_Analysis[Orders]) -> 1551 | AX4: =SUMIF(Customer_Analysis[Customer Type],AU4,Customer_Analysis[Units Sold]) -> 4622 | AY4: =SUMIF(Customer_Analysis[Customer Type],AU4,Customer_Analysis[Revenue]) -> 64466271 | AZ4: =SUMIF(Customer_Analysis[Customer Type],AU4,Customer_Analysis[Profit]) -> 8910939.8 | BA4: =AZ4/AY4 -> 0.13822639 | BB4: =AY4/AV4 -> 113496.96 | BC4: =AZ4/AV4 -> 15688.274 | BD4: =AW4/AV4 -> 2.7306338 | BE4: ="₹"&TEXT(Customer_Segment_Analysis[[#This Row],[Revenue]]/10000000,"0.00")&" Cr" -> ₹6.45 Cr | BG4: 2 | BH4: C0416 | BI4: Krish Kapoor | BJ4: 8 | BK4: 638645.89 | BL4: 65781.6 | BN4: 2 | BO4: C0296 | BP4: Kunal Kaur | BQ4: 7 | BR4: 513962.99 | BS4: 88176.92 | BU4: Corporate | BV4: =COUNTIF(RawData[Sales_Channel],BU4) -> 201 | BW4: =SUMIF(RawData[Sales_Channel],BU4,RawData[Quantity]) -> 595 | BX4: =SUMIF(RawData[Sales_Channel],BU4,RawData[Revenue]) -> 7696048.1 | BY4: =SUMIF(RawData[Sales_Channel],BU4,RawData[Profit]) -> 1110137.6 | BZ4: =BY4/BX4 -> 0.14424775 | CA4: ="₹"&TEXT(Sales_Channel_Analysis[[#This Row],[Revenue]]/10000000,"0.00")&" Cr" -> ₹0.77 Cr | CC4: Credit Card | CD4: =COUNTIF(RawData[Payment_Mode],CC4) -> 743 | CE4: =SUMIF(RawData[Payment_Mode],CC4,RawData[Quantity]) -> 2207 | CF4: =SUMIF(RawData[Payment_Mode],CC4,RawData[Revenue]) -> 30885641 | CG4: =SUMIF(RawData[Payment_Mode],CC4,RawData[Profit]) -> 4374285 | CH4: =CG4/CF4 -> 0.14162843 | CI4: ="₹"&TEXT(Payment_Mode_Analysis[[#This Row],[Revenue]]/10000000,"0.00")&" Cr" -> ₹3.09 Cr | CK4: S002 | CL4: Priya Shah | CM4: =COUNTIF(RawData[Salesperson_ID],CK4) -> 287 | CN4: =SUMIF(RawData[Salesperson_ID],CK4,RawData[Quantity]) -> 854 | CO4: =SUMIF(RawData[Salesperson_ID],CK4,RawData[Revenue]) -> 11599043 | CP4: =SUMIF(RawData[Salesperson_ID],CK4,RawData[Profit]) -> 1558798 | CQ4: =CP4/CO4 -> 0.13439023 | CR4: =IF(CM4=0,0,CO4/CM4) -> 40414.783 | CS4: ="₹"&TEXT(Table29[[#This Row],[Revenue]]/10000000,"0.00")&" Cr" -> ₹1.16 Cr | CU4: Pune | CV4: West | CW4: =COUNTIF(RawData[City],CU4) -> 219 | CX4: =SUMIF(RawData[City],CU4,RawData[Quantity]) -> 653 | CY4: =SUMIF(RawData[City],CU4,RawData[Revenue]) -> 7436394.5 | CZ4: =SUMIF(RawData[City],CU4,RawData[Profit]) -> 1043534.7 | DA4: =CZ4/CY4 -> 0.14032804 | DC4: South | DD4: =SUMIF(City_Analysis[Region],DC4,City_Analysis[Orders]) -> 783 | DE4: =SUMIF(City_Analysis[Region],DC4,City_Analysis[Units Sold]) -> 2385 | DF4: =SUMIF(City_Analysis[Region],DC4,City_Analysis[Revenue]) -> 31841025 | DG4: =SUMIF(City_Analysis[Region],DC4,City_Analysis[Profit]) -> 4381866.9 | DH4: =IF(DF4=0,0,DG4/DF4) -> 0.13761702 | DI4: ="₹"&TEXT(Region_Analysis[[#This Row],[Revenue]]/10000000,"0.00")&" Cr" -> ₹3.18 Cr | DK4: November | DL4: Furniture | DM4: =SUMIFS(RawData[Revenue],RawData[Product_Category],DL4, RawData[Order_Date],">="&DATE(2025,11,1),RawData[Order_Date],"<"&DATE(2025,12,1)) -> 3684981.1 | DN4: =SUMIFS(RawData[Profit],RawData[Product_Category],Profit_Drop_Analysis[[#This Row],[Category]], RawData[Order_Date],">="&DATE(2025,11,1),RawData[Order_Date],"<"&DATE(2025,12,1)) -> 284057.81 | DO4: =DN4/DM4 -> 0.077085282 | DQ4: Smartphone | DR4: =SUMIFS(RawData[Revenue],RawData[Product_Name],DQ4, RawData[Order_Date],">="&DATE(2025,11,1),RawData[Order_Date],"<"&DATE(2025,12,1)) -> 2016614 | DS4: =SUMIFS(RawData[Profit],RawData[Product_Name],DQ4, RawData[Order_Date],">="&DATE(2025,11,1),RawData[Order_Date],"<"&DATE(2025,12,1)) -> 155014 | DT4: =DS4/DR4 -> 0.076868454 | DU4: =SUMIFS(RawData[Revenue],RawData[Product_Name],DQ4, RawData[Order_Date],">="&DATE(2025,12,1),RawData[Order_Date],"<"&DATE(2026,1,1)) -> 1479972 | DV4: =SUMIFS(RawData[Profit],RawData[Product_Name],DQ4, RawData[Order_Date],">="&DATE(2025,12,1),RawData[Order_Date],"<"&DATE(2026,1,1)) -> 105252 | DW4: =DV4/DU4 -> 0.071117562 | DY4: February | DZ4: =MONTH(DY4&1) -> 2 | EA4: =SUMPRODUCT(--(MONTH(RawData[Order_Date])= DZ4)) -> 222 | EB4: =SUMPRODUCT((MONTH(RawData[Order_Date])=DZ4)*RawData[Quantity]) -> 658 | EC4: =SUMPRODUCT((MONTH(RawData[Order_Date])=DZ4)*RawData[Revenue]) -> 9441583.4 | ED4: =SUMPRODUCT((MONTH(RawData[Order_Date])=DZ4)*RawData[Profit]) -> 1413047.1 | EE4: =IFERROR(ED4/EC4,0) -> 0.14966209 | EG4: Smartphone | EH4: =VLOOKUP(EG4,Product_Analysis[[Product]:[Profit Margin]],7,FALSE) -> 0.13212207 | EI4: 0.076868454 | EJ4: =AVERAGEIFS(RawData[Discount%],RawData[Product_Name],EG4,RawData[Order_Date],">="&DATE(2025,11,1),RawData[Order_Date],"<"&DATE(2025,12,1)) -> 13.7 | EK4: 0.071117562 | EL4: =AVERAGEIFS(RawData[Discount%],RawData[Product_Name],EG4,RawData[Order_Date],">="&DATE(2025,12,1),RawData[Order_Date],"<"&DATE(2026,1,1)) -> 14.142857
A5: Unique Salespersons | B5: =SUMPRODUCT((RawData[Salesperson_ID]<>"")/COUNTIF(RawData[Salesperson_ID],RawData[Salesperson_ID]&"")) -> 10 | D5: Office Supplies | E5: =COUNTIF(RawData[Product_Category],"Office Supplies") -> 712 | F5: =SUMIF(RawData[Product_Category],"Office Supplies",RawData[Quantity]) -> 2146 | G5: =SUMIF(RawData[Product_Category],"Office Supplies",RawData[Revenue]) -> 498079.2 | H5: =SUMIF(RawData[Product_Category],"Office Supplies",RawData[Total_Cost]) -> 360491.7 | I5: =SUMIF(RawData[Product_Category],"Office Supplies",RawData[Profit]) -> 137587.5 | J5: =I5/G5 -> 0.27623619 | L5: March | M5: =MONTH(L5&1) -> 3 | N5: =SUMPRODUCT(--(MONTH(RawData[Order_Date])= M5)) -> 263 | O5: =SUMPRODUCT((MONTH(RawData[Order_Date])=M5)*RawData[Quantity]) -> 806 | P5: =SUMPRODUCT((MONTH(RawData[Order_Date])=M5)*RawData[Revenue]) -> 11872561 | Q5: =SUMPRODUCT((MONTH(RawData[Order_Date])=M5)*RawData[Profit]) -> 1756436.4 | R5: =IFERROR(Q5/P5,0) -> 0.14794082 | T5: Furniture | U5: Regular | V5: =COUNTIFS(RawData[Product_Category],"Furniture",RawData[Order_Date],"<"&DATE(2025,11,1)) -> 688 | W5: =SUMIFS(RawData[Quantity],RawData[Product_Category],"Furniture",RawData[Order_Date],"<"&DATE(2025,11,1)) -> 2037 | X5: =SUMIFS(RawData[Revenue],RawData[Product_Category],"Furniture",RawData[Order_Date],"<"&DATE(2025,11,1)) -> 42783269 | Y5: =SUMIFS(RawData[Profit],RawData[Product_Category],"Furniture",RawData[Order_Date],"<"&DATE(2025,11,1)) -> 7242049.8 | Z5: =Y5/X5 -> 0.16927294 | AA5: ="₹"&TEXT(Category_and_Seasonal_Analysis[[#This Row],[Revenue]]/10000000,"0.00")&" Cr" -> ₹4.28 Cr | AB5: ="₹"&TEXT(Category_and_Seasonal_Analysis[[#This Row],[Profit]]/100000,"0.00")&" L" -> ₹72.42 L | AD5: Tablet | AE5: Electronics | AF5: =COUNTIF(RawData[Product_Name],AD5) -> 147 | AG5: =SUMIF(RawData[Product_Name],AD5,RawData[Quantity]) -> 439 | AH5: =SUMIF(RawData[Product_Name],AD5,RawData[Revenue]) -> 11092822 | AI5: =SUMIF(RawData[Product_Name],AD5,RawData[Profit]) -> 831569.76 | AJ5: =AI5/AH5 -> 0.074964674 | AL5: C0003 | AM5: Anjali Bose | AN5: =COUNTIF(RawData[Customer_ID],AL5) -> 5 | AO5: =SUMIF(RawData[Customer_ID],AL5,RawData[Quantity]) -> 19 | AP5: =SUMIF(RawData[Customer_ID],AL5,RawData[Revenue]) -> 403024.2 | AQ5: =SUMIF(RawData[Customer_ID],AL5,RawData[Profit]) -> 49883.3 | AR5: =IF(AN5=0,0,AP5/AN5) -> 80604.84 | AS5: =IF(AN5=1,"One-time",IF(AN5<=4,"Occasional",IF(AN5<=8,"Loyal","Review"))) -> Loyal | AU5: Loyal | AV5: =COUNTIF(Customer_Analysis[Customer Type],AU5) -> 221 | AW5: =SUMIF(Customer_Analysis[Customer Type],AU5,Customer_Analysis[Orders]) -> 1255 | AX5: =SUMIF(Customer_Analysis[Customer Type],AU5,Customer_Analysis[Units Sold]) -> 3802 | AY5: =SUMIF(Customer_Analysis[Customer Type],AU5,Customer_Analysis[Revenue]) -> 52523828 | AZ5: =SUMIF(Customer_Analysis[Customer Type],AU5,Customer_Analysis[Profit]) -> 7267728.5 | BA5: =AZ5/AY5 -> 0.13837012 | BB5: =AY5/AV5 -> 237664.38 | BC5: =AZ5/AV5 -> 32885.649 | BD5: =AW5/AV5 -> 5.678733 | BE5: ="₹"&TEXT(Customer_Segment_Analysis[[#This Row],[Revenue]]/10000000,"0.00")&" Cr" -> ₹5.25 Cr | BG5: 3 | BH5: C0279 | BI5: Manav Rao | BJ5: 5 | BK5: 613493.55 | BL5: 85385.9 | BN5: 3 | BO5: C0279 | BP5: Manav Rao | BQ5: 5 | BR5: 613493.55 | BS5: 85385.9 | BU5: In-Store | BV5: =COUNTIF(RawData[Sales_Channel],BU5) -> 1660 | BW5: =SUMIF(RawData[Sales_Channel],BU5,RawData[Quantity]) -> 5083 | BX5: =SUMIF(RawData[Sales_Channel],BU5,RawData[Revenue]) -> 70213180 | BY5: =SUMIF(RawData[Sales_Channel],BU5,RawData[Profit]) -> 9582905.5 | BZ5: =BY5/BX5 -> 0.136483 | CA5: ="₹"&TEXT(Sales_Channel_Analysis[[#This Row],[Revenue]]/10000000,"0.00")&" Cr" -> ₹7.02 Cr | CC5: Debit Card | CD5: =COUNTIF(RawData[Payment_Mode],CC5) -> 638 | CE5: =SUMIF(RawData[Payment_Mode],CC5,RawData[Quantity]) -> 1933 | CF5: =SUMIF(RawData[Payment_Mode],CC5,RawData[Revenue]) -> 27155932 | CG5: =SUMIF(RawData[Payment_Mode],CC5,RawData[Profit]) -> 3724089.7 | CH5: =CG5/CF5 -> 0.13713724 | CI5: ="₹"&TEXT(Payment_Mode_Analysis[[#This Row],[Revenue]]/10000000,"0.00")&" Cr" -> ₹2.72 Cr | CK5: S003 | CL5: Rahul Sharma | CM5: =COUNTIF(RawData[Salesperson_ID],CK5) -> 303 | CN5: =SUMIF(RawData[Salesperson_ID],CK5,RawData[Quantity]) -> 932 | CO5: =SUMIF(RawData[Salesperson_ID],CK5,RawData[Revenue]) -> 10613170 | CP5: =SUMIF(RawData[Salesperson_ID],CK5,RawData[Profit]) -> 1477921.4 | CQ5: =CP5/CO5 -> 0.13925353 | CR5: =IF(CM5=0,0,CO5/CM5) -> 35026.964 | CS5: ="₹"&TEXT(Table29[[#This Row],[Revenue]]/10000000,"0.00")&" Cr" -> ₹1.06 Cr | CU5: Ahmedabad | CV5: West | CW5: =COUNTIF(RawData[City],CU5) -> 205 | CX5: =SUMIF(RawData[City],CU5,RawData[Quantity]) -> 609 | CY5: =SUMIF(RawData[City],CU5,RawData[Revenue]) -> 8732321 | CZ5: =SUMIF(RawData[City],CU5,RawData[Profit]) -> 1189644.5 | DA5: =CZ5/CY5 -> 0.13623463 | DC5: East | DD5: =SUMIF(City_Analysis[Region],DC5,City_Analysis[Orders]) -> 269 | DE5: =SUMIF(City_Analysis[Region],DC5,City_Analysis[Units Sold]) -> 792 | DF5: =SUMIF(City_Analysis[Region],DC5,City_Analysis[Revenue]) -> 10920469 | DG5: =SUMIF(City_Analysis[Region],DC5,City_Analysis[Profit]) -> 1516997.4 | DH5: =IF(DF5=0,0,DG5/DF5) -> 0.13891321 | DI5: ="₹"&TEXT(Region_Analysis[[#This Row],[Revenue]]/10000000,"0.00")&" Cr" -> ₹1.09 Cr | DK5: November | DL5: Office Supplies | DM5: =SUMIFS(RawData[Revenue],RawData[Product_Category],DL5, RawData[Order_Date],">="&DATE(2025,11,1),RawData[Order_Date],"<"&DATE(2025,12,1)) -> 41029.5 | DN5: =SUMIFS(RawData[Profit],RawData[Product_Category],Profit_Drop_Analysis[[#This Row],[Category]], RawData[Order_Date],">="&DATE(2025,11,1),RawData[Order_Date],"<"&DATE(2025,12,1)) -> 11104.5 | DO5: =DN5/DM5 -> 0.27064673 | DQ5: Tablet | DR5: =SUMIFS(RawData[Revenue],RawData[Product_Name],DQ5, RawData[Order_Date],">="&DATE(2025,11,1),RawData[Order_Date],"<"&DATE(2025,12,1)) -> 702599.45 | DS5: =SUMIFS(RawData[Profit],RawData[Product_Name],DQ5, RawData[Order_Date],">="&DATE(2025,11,1),RawData[Order_Date],"<"&DATE(2025,12,1)) -> 1374.95 | DT5: =DS5/DR5 -> 0.0019569472 | DU5: =SUMIFS(RawData[Revenue],RawData[Product_Name],DQ5, RawData[Order_Date],">="&DATE(2025,12,1),RawData[Order_Date],"<"&DATE(2026,1,1)) -> 1507770.2 | DV5: =SUMIFS(RawData[Profit],RawData[Product_Name],DQ5, RawData[Order_Date],">="&DATE(2025,12,1),RawData[Order_Date],"<"&DATE(2026,1,1)) -> 11824.57 | DW5: =DV5/DU5 -> 0.007842422 | DY5: March | DZ5: =MONTH(DY5&1) -> 3 | EA5: =SUMPRODUCT(--(MONTH(RawData[Order_Date])= DZ5)) -> 263 | EB5: =SUMPRODUCT((MONTH(RawData[Order_Date])=DZ5)*RawData[Quantity]) -> 806 | EC5: =SUMPRODUCT((MONTH(RawData[Order_Date])=DZ5)*RawData[Revenue]) -> 11872561 | ED5: =SUMPRODUCT((MONTH(RawData[Order_Date])=DZ5)*RawData[Profit]) -> 1756436.4 | EE5: =IFERROR(ED5/EC5,0) -> 0.14794082 | EG5: Tablet | EH5: =VLOOKUP(EG5,Product_Analysis[[Product]:[Profit Margin]],7,FALSE) -> 0.074964674 | EI5: 0.0019569472 | EJ5: =AVERAGEIFS(RawData[Discount%],RawData[Product_Name],EG5,RawData[Order_Date],">="&DATE(2025,11,1),RawData[Order_Date],"<"&DATE(2025,12,1)) -> 14.545455 | EK5: 0.007842422 | EL5: =AVERAGEIFS(RawData[Discount%],RawData[Product_Name],EG5,RawData[Order_Date],">="&DATE(2025,12,1),RawData[Order_Date],"<"&DATE(2026,1,1)) -> 14.421053
A6: Total Quantity Sold | B6: =SUM(RawData[Quantity]) -> 9029 | L6: April | M6: =MONTH(L6&1) -> 4 | N6: =SUMPRODUCT(--(MONTH(RawData[Order_Date])= M6)) -> 258 | O6: =SUMPRODUCT((MONTH(RawData[Order_Date])=M6)*RawData[Quantity]) -> 756 | P6: =SUMPRODUCT((MONTH(RawData[Order_Date])=M6)*RawData[Revenue]) -> 10348640 | Q6: =SUMPRODUCT((MONTH(RawData[Order_Date])=M6)*RawData[Profit]) -> 1585968.6 | R6: =IFERROR(Q6/P6,0) -> 0.15325382 | T6: Furniture | U6: Festival | V6: =COUNTIFS(RawData[Product_Category],"Furniture",RawData[Order_Date],">="&DATE(2025,11,1)) -> 128 | W6: =SUMIFS(RawData[Quantity],RawData[Product_Category],"Furniture",RawData[Order_Date],">="&DATE(2025,11,1)) -> 386 | X6: =SUMIFS(RawData[Revenue],RawData[Product_Category],"Furniture",RawData[Order_Date],">="&DATE(2025,11,1)) -> 6935300.1 | Y6: =SUMIFS(RawData[Profit],RawData[Product_Category],"Furniture",RawData[Order_Date],">="&DATE(2025,11,1)) -> 555861.24 | Z6: =Y6/X6 -> 0.080149559 | AA6: ="₹"&TEXT(Category_and_Seasonal_Analysis[[#This Row],[Revenue]]/10000000,"0.00")&" Cr" -> ₹0.69 Cr | AB6: ="₹"&TEXT(Category_and_Seasonal_Analysis[[#This Row],[Profit]]/100000,"0.00")&" L" -> ₹5.56 L | AD6: Monitor | AE6: Electronics | AF6: =COUNTIF(RawData[Product_Name],AD6) -> 156 | AG6: =SUMIF(RawData[Product_Name],AD6,RawData[Quantity]) -> 459 | AH6: =SUMIF(RawData[Product_Name],AD6,RawData[Revenue]) -> 7016694.7 | AI6: =SUMIF(RawData[Product_Name],AD6,RawData[Profit]) -> 352418.64 | AJ6: =AI6/AH6 -> 0.050225734 | AL6: C0004 | AM6: Akash Kapoor | AN6: =COUNTIF(RawData[Customer_ID],AL6) -> 4 | AO6: =SUMIF(RawData[Customer_ID],AL6,RawData[Quantity]) -> 19 | AP6: =SUMIF(RawData[Customer_ID],AL6,RawData[Revenue]) -> 426610.65 | AQ6: =SUMIF(RawData[Customer_ID],AL6,RawData[Profit]) -> 65613.7 | AR6: =IF(AN6=0,0,AP6/AN6) -> 106652.66 | AS6: =IF(AN6=1,"One-time",IF(AN6<=4,"Occasional",IF(AN6<=8,"Loyal","Review"))) -> Occasional | AU6: Review | AV6: =COUNTIF(Customer_Analysis[Customer Type],AU6) -> 10 | AW6: =SUMIF(Customer_Analysis[Customer Type],AU6,Customer_Analysis[Orders]) -> 93 | AX6: =SUMIF(Customer_Analysis[Customer Type],AU6,Customer_Analysis[Units Sold]) -> 284 | AY6: =SUMIF(Customer_Analysis[Customer Type],AU6,Customer_Analysis[Revenue]) -> 3239528.1 | AZ6: =SUMIF(Customer_Analysis[Customer Type],AU6,Customer_Analysis[Profit]) -> 430379.46 | BA6: =AZ6/AY6 -> 0.13285251 | BB6: =AY6/AV6 -> 323952.82 | BC6: =AZ6/AV6 -> 43037.946 | BD6: =AW6/AV6 -> 9.3 | BE6: ="₹"&TEXT(Customer_Segment_Analysis[[#This Row],[Revenue]]/10000000,"0.00")&" Cr" -> ₹0.32 Cr | BG6: 4 | BH6: C0846 | BI6: Nikita Saxena | BJ6: 7 | BK6: 586628.8 | BL6: 89714.14 | BN6: 4 | BO6: C0316 | BP6: Nandini Fernandes | BQ6: 10 | BR6: 506960.31 | BS6: 83565.66 | BU6: total | BV6: =SUM(BV3:BV5) -> 3000 | BW6: =SUM(BW3:BW5) -> 9029 | BX6: =SUM(BX3:BX5) -> 1.2407907e+08 | BY6: =SUM(BY3:BY5) -> 17118773 | BZ6: =SUM(BZ3:BZ5) -> 0.41990667 | CA6: ="₹"&TEXT(Sales_Channel_Analysis[[#This Row],[Revenue]]/10000000,"0.00")&" Cr" -> ₹12.41 Cr | CC6: Cash | CD6: =COUNTIF(RawData[Payment_Mode],CC6) -> 307 | CE6: =SUMIF(RawData[Payment_Mode],CC6,RawData[Quantity]) -> 881 | CF6: =SUMIF(RawData[Payment_Mode],CC6,RawData[Revenue]) -> 11258890 | CG6: =SUMIF(RawData[Payment_Mode],CC6,RawData[Profit]) -> 1493053.4 | CH6: =CG6/CF6 -> 0.13261107 | CI6: ="₹"&TEXT(Payment_Mode_Analysis[[#This Row],[Revenue]]/10000000,"0.00")&" Cr" -> ₹1.13 Cr | CK6: S004 | CL6: Sneha Mehta | CM6: =COUNTIF(RawData[Salesperson_ID],CK6) -> 299 | CN6: =SUMIF(RawData[Salesperson_ID],CK6,RawData[Quantity]) -> 900 | CO6: =SUMIF(RawData[Salesperson_ID],CK6,RawData[Revenue]) -> 12620581 | CP6: =SUMIF(RawData[Salesperson_ID],CK6,RawData[Profit]) -> 1805729.8 | CQ6: =CP6/CO6 -> 0.14307818 | CR6: =IF(CM6=0,0,CO6/CM6) -> 42209.301 | CS6: ="₹"&TEXT(Table29[[#This Row],[Revenue]]/10000000,"0.00")&" Cr" -> ₹1.26 Cr | CU6: Indore | CV6: West | CW6: =COUNTIF(RawData[City],CU6) -> 272 | CX6: =SUMIF(RawData[City],CU6,RawData[Quantity]) -> 871 | CY6: =SUMIF(RawData[City],CU6,RawData[Revenue]) -> 13301066 | CZ6: =SUMIF(RawData[City],CU6,RawData[Profit]) -> 1834841.4 | DA6: =CZ6/CY6 -> 0.13794694 | DC6: West | DD6: =SUMIF(City_Analysis[Region],DC6,City_Analysis[Orders]) -> 1199 | DE6: =SUMIF(City_Analysis[Region],DC6,City_Analysis[Units Sold]) -> 3581 | DF6: =SUMIF(City_Analysis[Region],DC6,City_Analysis[Revenue]) -> 50096317 | DG6: =SUMIF(City_Analysis[Region],DC6,City_Analysis[Profit]) -> 6874817.9 | DH6: =IF(DF6=0,0,DG6/DF6) -> 0.137232 | DI6: ="₹"&TEXT(Region_Analysis[[#This Row],[Revenue]]/10000000,"0.00")&" Cr" -> ₹5.01 Cr | DK6: December | DL6: Electronics | DM6: =SUMIFS(RawData[Revenue],RawData[Product_Category],DL6, RawData[Order_Date],">="&DATE(2025,12,1),RawData[Order_Date],"<"&DATE(2026,1,1)) -> 5965907.6 | DN6: =SUMIFS(RawData[Profit],RawData[Product_Category],Profit_Drop_Analysis[[#This Row],[Category]], RawData[Order_Date],">="&DATE(2025,12,1),RawData[Order_Date],"<"&DATE(2026,1,1)) -> 280477.73 | DO6: =DN6/DM6 -> 0.047013422 | DQ6: Monitor | DR6: =SUMIFS(RawData[Revenue],RawData[Product_Name],DQ6, RawData[Order_Date],">="&DATE(2025,11,1),RawData[Order_Date],"<"&DATE(2025,12,1)) -> 501239.62 | DS6: =SUMIFS(RawData[Profit],RawData[Product_Name],DQ6, RawData[Order_Date],">="&DATE(2025,11,1),RawData[Order_Date],"<"&DATE(2025,12,1)) -> -6929.58 | DT6: =DS6/DR6 -> -0.013824885 | DU6: =SUMIFS(RawData[Revenue],RawData[Product_Name],DQ6, RawData[Order_Date],">="&DATE(2025,12,1),RawData[Order_Date],"<"&DATE(2026,1,1)) -> 725626.02 | DV6: =SUMIFS(RawData[Profit],RawData[Product_Name],DQ6, RawData[Order_Date],">="&DATE(2025,12,1),RawData[Order_Date],"<"&DATE(2026,1,1)) -> -14849.1 | DW6: =DV6/DU6 -> -0.020463847 | DY6: April | DZ6: =MONTH(DY6&1) -> 4 | EA6: =SUMPRODUCT(--(MONTH(RawData[Order_Date])= DZ6)) -> 258 | EB6: =SUMPRODUCT((MONTH(RawData[Order_Date])=DZ6)*RawData[Quantity]) -> 756 | EC6: =SUMPRODUCT((MONTH(RawData[Order_Date])=DZ6)*RawData[Revenue]) -> 10348640 | ED6: =SUMPRODUCT((MONTH(RawData[Order_Date])=DZ6)*RawData[Profit]) -> 1585968.6 | EE6: =IFERROR(ED6/EC6,0) -> 0.15325382 | EG6: Monitor | EH6: =VLOOKUP(EG6,Product_Analysis[[Product]:[Profit Margin]],7,FALSE) -> 0.050225734 | EI6: -0.013824885 | EJ6: =AVERAGEIFS(RawData[Discount%],RawData[Product_Name],EG6,RawData[Order_Date],">="&DATE(2025,11,1),RawData[Order_Date],"<"&DATE(2025,12,1)) -> 13.25 | EK6: -0.020463847 | EL6: =AVERAGEIFS(RawData[Discount%],RawData[Product_Name],EG6,RawData[Order_Date],">="&DATE(2025,12,1),RawData[Order_Date],"<"&DATE(2026,1,1)) -> 13.666667
A7: Earliest Order Date | B7: =MIN(RawData[Order_Date]) -> 45658 | L7: May | M7: =MONTH(L7&1) -> 5 | N7: =SUMPRODUCT(--(MONTH(RawData[Order_Date])= M7)) -> 229 | O7: =SUMPRODUCT((MONTH(RawData[Order_Date])=M7)*RawData[Quantity]) -> 674 | P7: =SUMPRODUCT((MONTH(RawData[Order_Date])=M7)*RawData[Revenue]) -> 8656122.3 | Q7: =SUMPRODUCT((MONTH(RawData[Order_Date])=M7)*RawData[Profit]) -> 1332230.5 | R7: =IFERROR(Q7/P7,0) -> 0.15390615 | T7: Office Supplies | U7: Regular | V7: =COUNTIFS(RawData[Product_Category],"Office Supplies",RawData[Order_Date],"<"&DATE(2025,11,1)) -> 597 | W7: =SUMIFS(RawData[Quantity],RawData[Product_Category],"Office Supplies",RawData[Order_Date],"<"&DATE(2025,11,1)) -> 1795 | X7: =SUMIFS(RawData[Revenue],RawData[Product_Category],"Office Supplies",RawData[Order_Date],"<"&DATE(2025,11,1)) -> 407947 | Y7: =SUMIFS(RawData[Profit],RawData[Product_Category],"Office Supplies",RawData[Order_Date],"<"&DATE(2025,11,1)) -> 113119 | Z7: =Y7/X7 -> 0.27728847 | AA7: ="₹"&TEXT(Category_and_Seasonal_Analysis[[#This Row],[Revenue]]/10000000,"0.00")&" Cr" -> ₹0.04 Cr | AB7: ="₹"&TEXT(Category_and_Seasonal_Analysis[[#This Row],[Profit]]/100000,"0.00")&" L" -> ₹1.13 L | AD7: Printer | AE7: Electronics | AF7: =COUNTIF(RawData[Product_Name],AD7) -> 129 | AG7: =SUMIF(RawData[Product_Name],AD7,RawData[Quantity]) -> 382 | AH7: =SUMIF(RawData[Product_Name],AD7,RawData[Revenue]) -> 4902068.5 | AI7: =SUMIF(RawData[Product_Name],AD7,RawData[Profit]) -> 700374.06 | AJ7: =AI7/AH7 -> 0.14287317 | AL7: C0005 | AM7: Bhavya Kapoor | AN7: =COUNTIF(RawData[Customer_ID],AL7) -> 2 | AO7: =SUMIF(RawData[Customer_ID],AL7,RawData[Quantity]) -> 8 | AP7: =SUMIF(RawData[Customer_ID],AL7,RawData[Revenue]) -> 116842.69 | AQ7: =SUMIF(RawData[Customer_ID],AL7,RawData[Profit]) -> 19273.66 | AR7: =IF(AN7=0,0,AP7/AN7) -> 58421.345 | AS7: =IF(AN7=1,"One-time",IF(AN7<=4,"Occasional",IF(AN7<=8,"Loyal","Review"))) -> Occasional | AU7: total | AV7: =SUM(AV3:AV6) -> 900 | AW7: =SUM(AW3:AW6) -> 3000 | AX7: =SUM(AX3:AX6) -> 9029 | AY7: =SUM(AY3:AY6) -> 1.2407907e+08 | AZ7: =SUM(AZ3:AZ6) -> 17118773 | BA7: =AZ7/AY7 -> 0.13796665 | BG7: 5 | BH7: C0749 | BI7: Rohit Menon | BJ7: 6 | BK7: 582797.79 | BL7: 73254.61 | BN7: 5 | BO7: C0793 | BP7: Charu Parmar | BQ7: 6 | BR7: 569033.95 | BS7: 83347.99 | CC7: Net Banking | CD7: =COUNTIF(RawData[Payment_Mode],CC7) -> 152 | CE7: =SUMIF(RawData[Payment_Mode],CC7,RawData[Quantity]) -> 460 | CF7: =SUMIF(RawData[Payment_Mode],CC7,RawData[Revenue]) -> 6334631.4 | CG7: =SUMIF(RawData[Payment_Mode],CC7,RawData[Profit]) -> 911660.63 | CH7: =CG7/CF7 -> 0.14391692 | CI7: ="₹"&TEXT(Payment_Mode_Analysis[[#This Row],[Revenue]]/10000000,"0.00")&" Cr" -> ₹0.63 Cr | CK7: S005 | CL7: Vivek Gupta | CM7: =COUNTIF(RawData[Salesperson_ID],CK7) -> 325 | CN7: =SUMIF(RawData[Salesperson_ID],CK7,RawData[Quantity]) -> 1002 | CO7: =SUMIF(RawData[Salesperson_ID],CK7,RawData[Revenue]) -> 14075883 | CP7: =SUMIF(RawData[Salesperson_ID],CK7,RawData[Profit]) -> 1954828.8 | CQ7: =CP7/CO7 -> 0.13887788 | CR7: =IF(CM7=0,0,CO7/CM7) -> 43310.41 | CS7: ="₹"&TEXT(Table29[[#This Row],[Revenue]]/10000000,"0.00")&" Cr" -> ₹1.41 Cr | CU7: Nagpur | CV7: West | CW7: =COUNTIF(RawData[City],CU7) -> 265 | CX7: =SUMIF(RawData[City],CU7,RawData[Quantity]) -> 754 | CY7: =SUMIF(RawData[City],CU7,RawData[Revenue]) -> 10790921 | CZ7: =SUMIF(RawData[City],CU7,RawData[Profit]) -> 1471183.3 | DA7: =CZ7/CY7 -> 0.13633528 | DD7: =SUM(DD3:DD6) -> 3000 | DE7: =SUM(DE3:DE6) -> 9029 | DF7: =SUM(DF3:DF6) -> 1.2407907e+08 | DG7: =SUM(DG3:DG6) -> 17118773 | DK7: December | DL7: Furniture | DM7: =SUMIFS(RawData[Revenue],RawData[Product_Category],Profit_Drop_Analysis[[#This Row],[Category]], RawData[Order_Date],">="&DATE(2025,12,1),RawData[Order_Date],"<"&DATE(2026,1,1)) -> 3250319 | DN7: =SUMIFS(RawData[Profit],RawData[Product_Category],Profit_Drop_Analysis[[#This Row],[Category]], RawData[Order_Date],">="&DATE(2025,12,1),RawData[Order_Date],"<"&DATE(2026,1,1)) -> 271803.43 | DO7: =DN7/DM7 -> 0.083623618 | DQ7: Printer | DR7: =SUMIFS(RawData[Revenue],RawData[Product_Name],DQ7, RawData[Order_Date],">="&DATE(2025,11,1),RawData[Order_Date],"<"&DATE(2025,12,1)) -> 310727.4 | DS7: =SUMIFS(RawData[Profit],RawData[Product_Name],DQ7, RawData[Order_Date],">="&DATE(2025,11,1),RawData[Order_Date],"<"&DATE(2025,12,1)) -> 24748.2 | DT7: =DS7/DR7 -> 0.079646018 | DU7: =SUMIFS(RawData[Revenue],RawData[Product_Name],DQ7, RawData[Order_Date],">="&DATE(2025,12,1),RawData[Order_Date],"<"&DATE(2026,1,1)) -> 287904.06 | DV7: =SUMIFS(RawData[Profit],RawData[Product_Name],DQ7, RawData[Order_Date],">="&DATE(2025,12,1),RawData[Order_Date],"<"&DATE(2026,1,1)) -> 23923.26 | DW7: =DV7/DU7 -> 0.083094556 | DY7: May | DZ7: =MONTH(DY7&1) -> 5 | EA7: =SUMPRODUCT(--(MONTH(RawData[Order_Date])= DZ7)) -> 229 | EB7: =SUMPRODUCT((MONTH(RawData[Order_Date])=DZ7)*RawData[Quantity]) -> 674 | EC7: =SUMPRODUCT((MONTH(RawData[Order_Date])=DZ7)*RawData[Revenue]) -> 8656122.3 | ED7: =SUMPRODUCT((MONTH(RawData[Order_Date])=DZ7)*RawData[Profit]) -> 1332230.5 | EE7: =IFERROR(ED7/EC7,0) -> 0.15390615 | EG7: Sofa | EH7: =VLOOKUP(EG7,Product_Analysis[[Product]:[Profit Margin]],7,FALSE) -> 0.15169884 | EI7: 0.071171421 | EJ7: =AVERAGEIFS(RawData[Discount%],RawData[Product_Name],EG7,RawData[Order_Date],">="&DATE(2025,11,1),RawData[Order_Date],"<"&DATE(2025,12,1)) -> 16.333333 | EK7: 8.16 | EL7: =AVERAGEIFS(RawData[Discount%],RawData[Product_Name],EG7,RawData[Order_Date],">="&DATE(2025,12,1),RawData[Order_Date],"<"&DATE(2026,1,1)) -> 14.916667
A8: Latest Order Date | B8: =MAX(RawData[Order_Date]) -> 46022 | L8: June | M8: =MONTH(L8&1) -> 6 | N8: =SUMPRODUCT(--(MONTH(RawData[Order_Date])= M8)) -> 236 | O8: =SUMPRODUCT((MONTH(RawData[Order_Date])=M8)*RawData[Quantity]) -> 720 | P8: =SUMPRODUCT((MONTH(RawData[Order_Date])=M8)*RawData[Revenue]) -> 10428620 | Q8: =SUMPRODUCT((MONTH(RawData[Order_Date])=M8)*RawData[Profit]) -> 1539638.1 | R8: =IFERROR(Q8/P8,0) -> 0.14763585 | T8: Office Supplies | U8: Festival | V8: =COUNTIFS(RawData[Product_Category],"Office Supplies",RawData[Order_Date],">="&DATE(2025,11,1)) -> 115 | W8: =SUMIFS(RawData[Quantity],RawData[Product_Category],"Office Supplies",RawData[Order_Date],">="&DATE(2025,11,1)) -> 351 | X8: =SUMIFS(RawData[Revenue],RawData[Product_Category],"Office Supplies",RawData[Order_Date],">="&DATE(2025,11,1)) -> 90132.2 | Y8: =SUMIFS(RawData[Profit],RawData[Product_Category],"Office Supplies",RawData[Order_Date],">="&DATE(2025,11,1)) -> 24468.5 | Z8: =Y8/X8 -> 0.27147346 | AA8: ="₹"&TEXT(Category_and_Seasonal_Analysis[[#This Row],[Revenue]]/10000000,"0.00")&" Cr" -> ₹0.01 Cr | AB8: ="₹"&TEXT(Category_and_Seasonal_Analysis[[#This Row],[Profit]]/100000,"0.00")&" L" -> ₹0.24 L | AD8: Smartwatch | AE8: Electronics | AF8: =COUNTIF(RawData[Product_Name],AD8) -> 165 | AG8: =SUMIF(RawData[Product_Name],AD8,RawData[Quantity]) -> 508 | AH8: =SUMIF(RawData[Product_Name],AD8,RawData[Revenue]) -> 4503000 | AI8: =SUMIF(RawData[Product_Name],AD8,RawData[Profit]) -> 1124800 | AJ8: =AI8/AH8 -> 0.24978903 | AL8: C0006 | AM8: Rudra Gupta | AN8: =COUNTIF(RawData[Customer_ID],AL8) -> 3 | AO8: =SUMIF(RawData[Customer_ID],AL8,RawData[Quantity]) -> 4 | AP8: =SUMIF(RawData[Customer_ID],AL8,RawData[Revenue]) -> 163266.32 | AQ8: =SUMIF(RawData[Customer_ID],AL8,RawData[Profit]) -> 18969.53 | AR8: =IF(AN8=0,0,AP8/AN8) -> 54422.107 | AS8: =IF(AN8=1,"One-time",IF(AN8<=4,"Occasional",IF(AN8<=8,"Loyal","Review"))) -> Occasional | BG8: 6 | BH8: C0793 | BI8: Charu Parmar | BJ8: 6 | BK8: 569033.95 | BL8: 83347.99 | BN8: 6 | BO8: C0012 | BP8: Trisha Jain | BQ8: 4 | BR8: 688035.24 | BS8: 83323.21 | CK8: S006 | CL8: Ananya Joshi | CM8: =COUNTIF(RawData[Salesperson_ID],CK8) -> 317 | CN8: =SUMIF(RawData[Salesperson_ID],CK8,RawData[Quantity]) -> 923 | CO8: =SUMIF(RawData[Salesperson_ID],CK8,RawData[Revenue]) -> 13496038 | CP8: =SUMIF(RawData[Salesperson_ID],CK8,RawData[Profit]) -> 1765422.1 | CQ8: =CP8/CO8 -> 0.1308104 | CR8: =IF(CM8=0,0,CO8/CM8) -> 42574.253 | CS8: ="₹"&TEXT(Table29[[#This Row],[Revenue]]/10000000,"0.00")&" Cr" -> ₹1.35 Cr | CU8: Delhi | CV8: North | CW8: =COUNTIF(RawData[City],CU8) -> 251 | CX8: =SUMIF(RawData[City],CU8,RawData[Quantity]) -> 777 | CY8: =SUMIF(RawData[City],CU8,RawData[Revenue]) -> 11014919 | CZ8: =SUMIF(RawData[City],CU8,RawData[Profit]) -> 1580572.9 | DA8: =CZ8/CY8 -> 0.14349384 | DK8: December | DL8: Office Supplies | DM8: =SUMIFS(RawData[Revenue],RawData[Product_Category],Profit_Drop_Analysis[[#This Row],[Category]], RawData[Order_Date],">="&DATE(2025,12,1),RawData[Order_Date],"<"&DATE(2026,1,1)) -> 49102.7 | DN8: =SUMIFS(RawData[Profit],RawData[Product_Category],Profit_Drop_Analysis[[#This Row],[Category]], RawData[Order_Date],">="&DATE(2025,12,1),RawData[Order_Date],"<"&DATE(2026,1,1)) -> 13364 | DO8: =DN8/DM8 -> 0.27216426 | DQ8: Smartwatch | DR8: =SUMIFS(RawData[Revenue],RawData[Product_Name],DQ8, RawData[Order_Date],">="&DATE(2025,11,1),RawData[Order_Date],"<"&DATE(2025,12,1)) -> 230470 | DS8: =SUMIFS(RawData[Profit],RawData[Product_Name],DQ8, RawData[Order_Date],">="&DATE(2025,11,1),RawData[Order_Date],"<"&DATE(2025,12,1)) -> 44270 | DT8: =DS8/DR8 -> 0.19208574 | DU8: =SUMIFS(RawData[Revenue],RawData[Product_Name],DQ8, RawData[Order_Date],">="&DATE(2025,12,1),RawData[Order_Date],"<"&DATE(2026,1,1)) -> 354825 | DV8: =SUMIFS(RawData[Profit],RawData[Product_Name],DQ8, RawData[Order_Date],">="&DATE(2025,12,1),RawData[Order_Date],"<"&DATE(2026,1,1)) -> 68875 | DW8: =DV8/DU8 -> 0.19410977 | DY8: June | DZ8: =MONTH(DY8&1) -> 6 | EA8: =SUMPRODUCT(--(MONTH(RawData[Order_Date])= DZ8)) -> 236 | EB8: =SUMPRODUCT((MONTH(RawData[Order_Date])=DZ8)*RawData[Quantity]) -> 720 | EC8: =SUMPRODUCT((MONTH(RawData[Order_Date])=DZ8)*RawData[Revenue]) -> 10428620 | ED8: =SUMPRODUCT((MONTH(RawData[Order_Date])=DZ8)*RawData[Profit]) -> 1539638.1 | EE8: =IFERROR(ED8/EC8,0) -> 0.14763585 | EG8: Dining Table | EH8: =VLOOKUP(EG8,Product_Analysis[[Product]:[Profit Margin]],7,FALSE) -> 0.14197211 | EI8: 0.054940186 | EJ8: =AVERAGEIFS(RawData[Discount%],RawData[Product_Name],EG8,RawData[Order_Date],">="&DATE(2025,11,1),RawData[Order_Date],"<"&DATE(2025,12,1)) -> 17 | EK8: 0.059203811 | EL8: =AVERAGEIFS(RawData[Discount%],RawData[Product_Name],EG8,RawData[Order_Date],">="&DATE(2025,12,1),RawData[Order_Date],"<"&DATE(2026,1,1)) -> 15.5
A9: Total Revenue | B9: =SUM(RawData[Revenue]) -> 1.2407907e+08 | L9: July | M9: =MONTH(L9&1) -> 7 | N9: =SUMPRODUCT(--(MONTH(RawData[Order_Date])= M9)) -> 246 | O9: =SUMPRODUCT((MONTH(RawData[Order_Date])=M9)*RawData[Quantity]) -> 754 | P9: =SUMPRODUCT((MONTH(RawData[Order_Date])=M9)*RawData[Revenue]) -> 11213253 | Q9: =SUMPRODUCT((MONTH(RawData[Order_Date])=M9)*RawData[Profit]) -> 1653414.4 | R9: =IFERROR(Q9/P9,0) -> 0.1474518 | AD9: External Hard Drive | AE9: Electronics | AF9: =COUNTIF(RawData[Product_Name],AD9) -> 146 | AG9: =SUMIF(RawData[Product_Name],AD9,RawData[Quantity]) -> 474 | AH9: =SUMIF(RawData[Product_Name],AD9,RawData[Revenue]) -> 3027513 | AI9: =SUMIF(RawData[Product_Name],AD9,RawData[Profit]) -> 312915 | AJ9: =AI9/AH9 -> 0.10335711 | AL9: C0007 | AM9: Diya Choudhary | AN9: =COUNTIF(RawData[Customer_ID],AL9) -> 2 | AO9: =SUMIF(RawData[Customer_ID],AL9,RawData[Quantity]) -> 7 | AP9: =SUMIF(RawData[Customer_ID],AL9,RawData[Revenue]) -> 18424.5 | AQ9: =SUMIF(RawData[Customer_ID],AL9,RawData[Profit]) -> 5327 | AR9: =IF(AN9=0,0,AP9/AN9) -> 9212.25 | AS9: =IF(AN9=1,"One-time",IF(AN9<=4,"Occasional",IF(AN9<=8,"Loyal","Review"))) -> Occasional | AW9: =SUM(Top_10_customers_by_revenue[Revenue])/SUM(Customer_Analysis[Revenue]) -> 0.046139923 | BG9: 7 | BH9: C0331 | BI9: Priya Pawar | BJ9: 5 | BK9: 519493.96 | BL9: 59319.53 | BN9: 7 | BO9: C0663 | BP9: Diya Shetty | BQ9: 6 | BR9: 464198.71 | BS9: 79057.39 | CK9: S007 | CL9: Rohit Desai | CM9: =COUNTIF(RawData[Salesperson_ID],CK9) -> 309 | CN9: =SUMIF(RawData[Salesperson_ID],CK9,RawData[Quantity]) -> 948 | CO9: =SUMIF(RawData[Salesperson_ID],CK9,RawData[Revenue]) -> 13439275 | CP9: =SUMIF(RawData[Salesperson_ID],CK9,RawData[Profit]) -> 1868245.7 | CQ9: =CP9/CO9 -> 0.13901388 | CR9: =IF(CM9=0,0,CO9/CM9) -> 43492.799 | CS9: ="₹"&TEXT(Table29[[#This Row],[Revenue]]/10000000,"0.00")&" Cr" -> ₹1.34 Cr | CU9: Jaipur | CV9: North | CW9: =COUNTIF(RawData[City],CU9) -> 245 | CX9: =SUMIF(RawData[City],CU9,RawData[Quantity]) -> 733 | CY9: =SUMIF(RawData[City],CU9,RawData[Revenue]) -> 9979978.3 | CZ9: =SUMIF(RawData[City],CU9,RawData[Profit]) -> 1382733.6 | DA9: =CZ9/CY9 -> 0.13855076 | DQ9: External Hard Drive | DR9: =SUMIFS(RawData[Revenue],RawData[Product_Name],DQ9, RawData[Order_Date],">="&DATE(2025,11,1),RawData[Order_Date],"<"&DATE(2025,12,1)) -> 260751 | DS9: =SUMIFS(RawData[Profit],RawData[Product_Name],DQ9, RawData[Order_Date],">="&DATE(2025,11,1),RawData[Order_Date],"<"&DATE(2025,12,1)) -> 8763 | DT9: =DS9/DR9 -> 0.033606774 | DU9: =SUMIFS(RawData[Revenue],RawData[Product_Name],DQ9, RawData[Order_Date],">="&DATE(2025,12,1),RawData[Order_Date],"<"&DATE(2026,1,1)) -> 202929 | DV9: =SUMIFS(RawData[Profit],RawData[Product_Name],DQ9, RawData[Order_Date],">="&DATE(2025,12,1),RawData[Order_Date],"<"&DATE(2026,1,1)) -> 8211 | DW9: =DV9/DU9 -> 0.040462428 | DY9: July | DZ9: =MONTH(DY9&1) -> 7 | EA9: =SUMPRODUCT(--(MONTH(RawData[Order_Date])= DZ9)) -> 246 | EB9: =SUMPRODUCT((MONTH(RawData[Order_Date])=DZ9)*RawData[Quantity]) -> 754 | EC9: =SUMPRODUCT((MONTH(RawData[Order_Date])=DZ9)*RawData[Revenue]) -> 11213253 | ED9: =SUMPRODUCT((MONTH(RawData[Order_Date])=DZ9)*RawData[Profit]) -> 1653414.4 | EE9: =IFERROR(ED9/EC9,0) -> 0.1474518 | EG9: Wardrobe | EH9: =VLOOKUP(EG9,Product_Analysis[[Product]:[Profit Margin]],7,FALSE) -> 0.13690553 | EI9: 3.75 | EJ9: =AVERAGEIFS(RawData[Discount%],RawData[Product_Name],EG9,RawData[Order_Date],">="&DATE(2025,11,1),RawData[Order_Date],"<"&DATE(2025,12,1)) -> 16.75 | EK9: 0.056300268 | EL9: =AVERAGEIFS(RawData[Discount%],RawData[Product_Name],EG9,RawData[Order_Date],">="&DATE(2025,12,1),RawData[Order_Date],"<"&DATE(2026,1,1)) -> 15.125
A10: Total Cost | B10: =SUM(RawData[Total_Cost]) -> 1.0696029e+08 | L10: August | M10: =MONTH(L10&1) -> 8 | N10: =SUMPRODUCT(--(MONTH(RawData[Order_Date])= M10)) -> 246 | O10: =SUMPRODUCT((MONTH(RawData[Order_Date])=M10)*RawData[Quantity]) -> 738 | P10: =SUMPRODUCT((MONTH(RawData[Order_Date])=M10)*RawData[Revenue]) -> 10899166 | Q10: =SUMPRODUCT((MONTH(RawData[Order_Date])=M10)*RawData[Profit]) -> 1601285.8 | R10: =IFERROR(Q10/P10,0) -> 0.1469182 | AD10: Earbuds | AE10: Electronics | AF10: =COUNTIF(RawData[Product_Name],AD10) -> 126 | AG10: =SUMIF(RawData[Product_Name],AD10,RawData[Quantity]) -> 366 | AH10: =SUMIF(RawData[Product_Name],AD10,RawData[Revenue]) -> 1221138.5 | AI10: =SUMIF(RawData[Product_Name],AD10,RawData[Profit]) -> 367077.5 | AJ10: =AI10/AH10 -> 0.30060268 | AL10: C0008 | AM10: Adarsh Verma | AN10: =COUNTIF(RawData[Customer_ID],AL10) -> 3 | AO10: =SUMIF(RawData[Customer_ID],AL10,RawData[Quantity]) -> 8 | AP10: =SUMIF(RawData[Customer_ID],AL10,RawData[Revenue]) -> 40020.05 | AQ10: =SUMIF(RawData[Customer_ID],AL10,RawData[Profit]) -> 10503.25 | AR10: =IF(AN10=0,0,AP10/AN10) -> 13340.017 | AS10: =IF(AN10=1,"One-time",IF(AN10<=4,"Occasional",IF(AN10<=8,"Loyal","Review"))) -> Occasional | BG10: 8 | BH10: C0296 | BI10: Kunal Kaur | BJ10: 7 | BK10: 513962.99 | BL10: 88176.92 | BN10: 8 | BO10: C0681 | BP10: Radhika Chatterjee | BQ10: 7 | BR10: 427904.55 | BS10: 74736.75 | CK10: S008 | CL10: Kavya Iyer | CM10: =COUNTIF(RawData[Salesperson_ID],CK10) -> 305 | CN10: =SUMIF(RawData[Salesperson_ID],CK10,RawData[Quantity]) -> 926 | CO10: =SUMIF(RawData[Salesperson_ID],CK10,RawData[Revenue]) -> 14729427 | CP10: =SUMIF(RawData[Salesperson_ID],CK10,RawData[Profit]) -> 2074756.4 | CQ10: =CP10/CO10 -> 0.14085792 | CR10: =IF(CM10=0,0,CO10/CM10) -> 48293.203 | CS10: ="₹"&TEXT(Table29[[#This Row],[Revenue]]/10000000,"0.00")&" Cr" -> ₹1.47 Cr | CU10: Lucknow | CV10: North | CW10: =COUNTIF(RawData[City],CU10) -> 253 | CX10: =SUMIF(RawData[City],CU10,RawData[Quantity]) -> 761 | CY10: =SUMIF(RawData[City],CU10,RawData[Revenue]) -> 10226360 | CZ10: =SUMIF(RawData[City],CU10,RawData[Profit]) -> 1381784.5 | DA10: =CZ10/CY10 -> 0.13511987 | DQ10: Earbuds | DR10: =SUMIFS(RawData[Revenue],RawData[Product_Name],DQ10, RawData[Order_Date],">="&DATE(2025,11,1),RawData[Order_Date],"<"&DATE(2025,12,1)) -> 110248.9 | DS10: =SUMIFS(RawData[Profit],RawData[Product_Name],DQ10, RawData[Order_Date],">="&DATE(2025,11,1),RawData[Order_Date],"<"&DATE(2025,12,1)) -> 26242.9 | DT10: =DS10/DR10 -> 0.23803321 | DU10: =SUMIFS(RawData[Revenue],RawData[Product_Name],DQ10, RawData[Order_Date],">="&DATE(2025,12,1),RawData[Order_Date],"<"&DATE(2026,1,1)) -> 78010.7 | DV10: =SUMIFS(RawData[Profit],RawData[Product_Name],DQ10, RawData[Order_Date],">="&DATE(2025,12,1),RawData[Order_Date],"<"&DATE(2026,1,1)) -> 19673.2 | DW10: =DV10/DU10 -> 0.25218592 | DY10: August | DZ10: =MONTH(DY10&1) -> 8 | EA10: =SUMPRODUCT(--(MONTH(RawData[Order_Date])= DZ10)) -> 246 | EB10: =SUMPRODUCT((MONTH(RawData[Order_Date])=DZ10)*RawData[Quantity]) -> 738 | EC10: =SUMPRODUCT((MONTH(RawData[Order_Date])=DZ10)*RawData[Revenue]) -> 10899166 | ED10: =SUMPRODUCT((MONTH(RawData[Order_Date])=DZ10)*RawData[Profit]) -> 1601285.8 | EE10: =IFERROR(ED10/EC10,0) -> 0.1469182
A11: Total Profit | B11: =SUM(RawData[Profit]) -> 17118773 | L11: September | M11: =MONTH(L11&1) -> 9 | N11: =SUMPRODUCT(--(MONTH(RawData[Order_Date])= M11)) -> 252 | O11: =SUMPRODUCT((MONTH(RawData[Order_Date])=M11)*RawData[Quantity]) -> 762 | P11: =SUMPRODUCT((MONTH(RawData[Order_Date])=M11)*RawData[Revenue]) -> 10035486 | Q11: =SUMPRODUCT((MONTH(RawData[Order_Date])=M11)*RawData[Profit]) -> 1510084 | R11: =IFERROR(Q11/P11,0) -> 0.15047442 | AD11: Keyboard | AE11: Electronics | AF11: =COUNTIF(RawData[Product_Name],AD11) -> 149 | AG11: =SUMIF(RawData[Product_Name],AD11,RawData[Quantity]) -> 431 | AH11: =SUMIF(RawData[Product_Name],AD11,RawData[Revenue]) -> 658581 | AI11: =SUMIF(RawData[Product_Name],AD11,RawData[Profit]) -> 231891 | AJ11: =AI11/AH11 -> 0.35210703 | AL11: C0009 | AM11: Krish Gupta | AN11: =COUNTIF(RawData[Customer_ID],AL11) -> 3 | AO11: =SUMIF(RawData[Customer_ID],AL11,RawData[Quantity]) -> 13 | AP11: =SUMIF(RawData[Customer_ID],AL11,RawData[Revenue]) -> 366981.94 | AQ11: =SUMIF(RawData[Customer_ID],AL11,RawData[Profit]) -> 38469.24 | AR11: =IF(AN11=0,0,AP11/AN11) -> 122327.31 | AS11: =IF(AN11=1,"One-time",IF(AN11<=4,"Occasional",IF(AN11<=8,"Loyal","Review"))) -> Occasional | BG11: 9 | BH11: C0316 | BI11: Nandini Fernandes | BJ11: 10 | BK11: 506960.31 | BL11: 83565.66 | BN11: 9 | BO11: C0749 | BP11: Rohit Menon | BQ11: 6 | BR11: 582797.79 | BS11: 73254.61 | CK11: S009 | CL11: Aditya Singh | CM11: =COUNTIF(RawData[Salesperson_ID],CK11) -> 281 | CN11: =SUMIF(RawData[Salesperson_ID],CK11,RawData[Quantity]) -> 850 | CO11: =SUMIF(RawData[Salesperson_ID],CK11,RawData[Revenue]) -> 11373643 | CP11: =SUMIF(RawData[Salesperson_ID],CK11,RawData[Profit]) -> 1570242 | CQ11: =CP11/CO11 -> 0.13805973 | CR11: =IF(CM11=0,0,CO11/CM11) -> 40475.596 | CS11: ="₹"&TEXT(Table29[[#This Row],[Revenue]]/10000000,"0.00")&" Cr" -> ₹1.14 Cr | CU11: Bengaluru | CV11: South | CW11: =COUNTIF(RawData[City],CU11) -> 242 | CX11: =SUMIF(RawData[City],CU11,RawData[Quantity]) -> 759 | CY11: =SUMIF(RawData[City],CU11,RawData[Revenue]) -> 11141384 | CZ11: =SUMIF(RawData[City],CU11,RawData[Profit]) -> 1452416.1 | DA11: =CZ11/CY11 -> 0.13036226 | DQ11: Keyboard | DR11: =SUMIFS(RawData[Revenue],RawData[Product_Name],DQ11, RawData[Order_Date],">="&DATE(2025,11,1),RawData[Order_Date],"<"&DATE(2025,12,1)) -> 67534.5 | DS11: =SUMIFS(RawData[Profit],RawData[Product_Name],DQ11, RawData[Order_Date],">="&DATE(2025,11,1),RawData[Order_Date],"<"&DATE(2025,12,1)) -> 21004.5 | DT11: =DS11/DR11 -> 0.31101881 | DU11: =SUMIFS(RawData[Revenue],RawData[Product_Name],DQ11, RawData[Order_Date],">="&DATE(2025,12,1),RawData[Order_Date],"<"&DATE(2026,1,1)) -> 36514.5 | DV11: =SUMIFS(RawData[Profit],RawData[Product_Name],DQ11, RawData[Order_Date],">="&DATE(2025,12,1),RawData[Order_Date],"<"&DATE(2026,1,1)) -> 10774.5 | DW11: =DV11/DU11 -> 0.29507456 | DY11: September | DZ11: =MONTH(DY11&1) -> 9 | EA11: =SUMPRODUCT(--(MONTH(RawData[Order_Date])= DZ11)) -> 252 | EB11: =SUMPRODUCT((MONTH(RawData[Order_Date])=DZ11)*RawData[Quantity]) -> 762 | EC11: =SUMPRODUCT((MONTH(RawData[Order_Date])=DZ11)*RawData[Revenue]) -> 10035486 | ED11: =SUMPRODUCT((MONTH(RawData[Order_Date])=DZ11)*RawData[Profit]) -> 1510084 | EE11: =IFERROR(ED11/EC11,0) -> 0.15047442
A12: Average Order Value | B12: =SUM(RawData[Revenue])/COUNTA(RawData[Order_ID]) -> 41359.689 | L12: October | M12: =MONTH(L12&1) -> 10 | N12: =SUMPRODUCT(--(MONTH(RawData[Order_Date])= M12)) -> 270 | O12: =SUMPRODUCT((MONTH(RawData[Order_Date])=M12)*RawData[Quantity]) -> 814 | P12: =SUMPRODUCT((MONTH(RawData[Order_Date])=M12)*RawData[Revenue]) -> 11273307 | Q12: =SUMPRODUCT((MONTH(RawData[Order_Date])=M12)*RawData[Profit]) -> 1741041.4 | R12: =IFERROR(Q12/P12,0) -> 0.15443928 | AD12: Mouse | AE12: Electronics | AF12: =COUNTIF(RawData[Product_Name],AD12) -> 139 | AG12: =SUMIF(RawData[Product_Name],AD12,RawData[Quantity]) -> 426 | AH12: =SUMIF(RawData[Product_Name],AD12,RawData[Revenue]) -> 433587 | AI12: =SUMIF(RawData[Product_Name],AD12,RawData[Profit]) -> 128997 | AJ12: =AI12/AH12 -> 0.29751123 | AL12: C0010 | AM12: Isha Singh | AN12: =COUNTIF(RawData[Customer_ID],AL12) -> 3 | AO12: =SUMIF(RawData[Customer_ID],AL12,RawData[Quantity]) -> 8 | AP12: =SUMIF(RawData[Customer_ID],AL12,RawData[Revenue]) -> 33153.4 | AQ12: =SUMIF(RawData[Customer_ID],AL12,RawData[Profit]) -> 6731.28 | AR12: =IF(AN12=0,0,AP12/AN12) -> 11051.133 | AS12: =IF(AN12=1,"One-time",IF(AN12<=4,"Occasional",IF(AN12<=8,"Loyal","Review"))) -> Occasional | BG12: 10 | BH12: C0072 | BI12: Vivaan Saxena | BJ12: 7 | BK12: 505946.16 | BL12: 62247.41 | BN12: 10 | BO12: C0833 | BP12: Charu Solanki | BQ12: 6 | BR12: 476531.68 | BS12: 70147.1 | CK12: S010 | CL12: Neha Verma | CM12: =COUNTIF(RawData[Salesperson_ID],CK12) -> 266 | CN12: =SUMIF(RawData[Salesperson_ID],CK12,RawData[Quantity]) -> 833 | CO12: =SUMIF(RawData[Salesperson_ID],CK12,RawData[Revenue]) -> 10408077 | CP12: =SUMIF(RawData[Salesperson_ID],CK12,RawData[Profit]) -> 1439303.2 | CQ12: =CP12/CO12 -> 0.13828714 | CR12: =IF(CM12=0,0,CO12/CM12) -> 39128.108 | CS12: ="₹"&TEXT(Table29[[#This Row],[Revenue]]/10000000,"0.00")&" Cr" -> ₹1.04 Cr | CU12: Hyderabad | CV12: South | CW12: =COUNTIF(RawData[City],CU12) -> 267 | CX12: =SUMIF(RawData[City],CU12,RawData[Quantity]) -> 831 | CY12: =SUMIF(RawData[City],CU12,RawData[Revenue]) -> 11216201 | CZ12: =SUMIF(RawData[City],CU12,RawData[Profit]) -> 1548696.3 | DA12: =CZ12/CY12 -> 0.13807672 | DQ12: Mouse | DR12: =SUMIFS(RawData[Revenue],RawData[Product_Name],DQ12, RawData[Order_Date],">="&DATE(2025,11,1),RawData[Order_Date],"<"&DATE(2025,12,1)) -> 36091 | DS12: =SUMIFS(RawData[Profit],RawData[Product_Name],DQ12, RawData[Order_Date],">="&DATE(2025,11,1),RawData[Order_Date],"<"&DATE(2025,12,1)) -> 8921 | DT12: =DS12/DR12 -> 0.24718074 | DU12: =SUMIFS(RawData[Revenue],RawData[Product_Name],DQ12, RawData[Order_Date],">="&DATE(2025,12,1),RawData[Order_Date],"<"&DATE(2026,1,1)) -> 36179 | DV12: =SUMIFS(RawData[Profit],RawData[Product_Name],DQ12, RawData[Order_Date],">="&DATE(2025,12,1),RawData[Order_Date],"<"&DATE(2026,1,1)) -> 8294 | DW12: =DV12/DU12 -> 0.22924901 | DY12: October | DZ12: =MONTH(DY12&1) -> 10 | EA12: =SUMPRODUCT(--(MONTH(RawData[Order_Date])= DZ12)) -> 270 | EB12: =SUMPRODUCT((MONTH(RawData[Order_Date])=DZ12)*RawData[Quantity]) -> 814 | EC12: =SUMPRODUCT((MONTH(RawData[Order_Date])=DZ12)*RawData[Revenue]) -> 11273307 | ED12: =SUMPRODUCT((MONTH(RawData[Order_Date])=DZ12)*RawData[Profit]) -> 1741041.4 | EE12: =IFERROR(ED12/EC12,0) -> 0.15443928
